Workbook
Name _2026: TABELLE!$F$3:$F$10
Name _2027: TABELLE!$G$3:$G$14
Name _2028: TABELLE!$H$3:$H$14
Name _2029: TABELLE!$I$3:$I$14
Name _copiacontratti: #REF!
Name _nuovoperconteggicontratti: #REF!
Name ANNO_COMPETENZA: TABELLE!$E$3:$E$7
Name Anno_release: TABELLE!$B$30:$C$74
Name ceci: #REF!
Name Contratti_conteggi_nuovo: #REF!
Name CROSS2021: #REF!
Name CROSS2022: #REF!
Name DvD_fine_NEG: #REF!
Name DvD_inizio_NEG: #REF!
Name LastRow_BV: #REF!
Name LastRow_PV: #REF!
Name LastRow_RP: #REF!
Name LastRow_RV: #REF!
Name MarkDifferenza: #REF!
Name MarkErogatoAllaData: #REF!
Name MarkInizialeOfferta: #REF!
Name MarkOrdine: #REF!
Name MarkPrevisione: #REF!
Name MENU_CLIENTE: #REF!
Name MENU_OWNER_FCST: #REF!
Name MENU_PROGETTO: #REF!
Name MENU_SPLIT_DSE: #REF!
Name MENU_STREAM: #REF!
Name NEW: #REF!
Name newone: #REF!
Name Risk_level: #REF!
Name Services: #REF!
Name SubCoEcomonics: #REF!
Name SubCoEcomonics: #REF!
Name SubCoEcomonics: #REF!
Name Tipi: #REF!
Name TotalePrevisioneCosti: #REF!
Name TotaleRicaviOrdine: #REF!

Sheet COMMESSE E FCST
B2: CAPGEMINI | L2: POSTE
B3: THOR | C3: PSO | D3: SAP Code | E3: Descrizione | F3: COV | G3: INVOICE | H3: DELTA INVOICE | I3: REVENUE | J3: DELTA REVENUE | L3: Contratto | M3: RIF. Contratto | N3: Data | O3: Imp. Lordo | P3: Sconto | Q3: Importo Netto | R3: Ordinato | S3: Da Ordinare | T3: Avanzato | U3: Da Avanzare
B4: OP# 02538791 | C4: 21108 | D4: IT010567-001 | E4: Logistica_AQ-4490015980_Task 2026 | F4: 3015556 | H4: =F4-G4 -> 3015556 | J4: =F4-I4 -> 3015556 | L4: BASE | M4: =CONTRATTO!C4 -> 4490015980 | N4: =CONTRATTO!D4 -> 46036 | O4: =CONTRATTO!E4 -> 6873049 | P4: =CONTRATTO!F4 -> 0 | Q4: =CONTRATTO!G4 -> 6873049 | R4: =CONTRATTO!H4 -> 38658 | S4: =CONTRATTO!I4 -> 6834391 | T4: =CONTRATTO!J4 -> 0 | U4: =CONTRATTO!K4 -> 0
B5: OP# 02538791_1 | C5: 21104 | D5: IT010567-002 | E5: Logistica_AQ-4490015980_Canone 2026 | F5: 77316 | H5: =F5-G5 -> 77316 | J5: =F5-I5 -> 77316 | L5: QDO | M5: =CONTRATTO!C5 -> 0 | N5: =CONTRATTO!D5 -> 0 | O5: =CONTRATTO!E5 -> 0 | P5: =CONTRATTO!F5 -> 0 | Q5: =CONTRATTO!G5 -> 0 | R5: =CONTRATTO!H5 -> 0 | S5: =CONTRATTO!I5 -> 0 | T5: =CONTRATTO!J5 -> 0 | U5: =CONTRATTO!K5 -> 0
H6: =F6-G6 -> 0 | J6: =F6-I6 -> 0 | L6: Proroga 1 | M6: =CONTRATTO!C6 -> 0 | N6: =CONTRATTO!D6 -> 0 | O6: =CONTRATTO!E6 -> 0 | P6: =CONTRATTO!F6 -> 0 | Q6: =CONTRATTO!G6 -> 0 | R6: =CONTRATTO!H6 -> 0 | S6: =CONTRATTO!I6 -> 0 | T6: =CONTRATTO!J6 -> 0 | U6: =CONTRATTO!K6 -> 0
H7: =F7-G7 -> 0 | J7: =F7-I7 -> 0 | L7: Proroga 2 | M7: =CONTRATTO!C7 -> 0 | N7: =CONTRATTO!D7 -> 0 | O7: =CONTRATTO!E7 -> 0 | P7: =CONTRATTO!F7 -> 0 | Q7: =CONTRATTO!G7 -> 0 | R7: =CONTRATTO!H7 -> 0 | S7: =CONTRATTO!I7 -> 0 | T7: =CONTRATTO!J7 -> 0 | U7: =CONTRATTO!K7 -> 0
H8: =F8-G8 -> 0 | J8: =F8-I8 -> 0 | L8: Proroga 3 | M8: =CONTRATTO!C8 -> 0 | N8: =CONTRATTO!D8 -> 0 | O8: =CONTRATTO!E8 -> 0 | P8: =CONTRATTO!F8 -> 0 | Q8: =CONTRATTO!G8 -> 0 | R8: =CONTRATTO!H8 -> 0 | S8: =CONTRATTO!I8 -> 0 | T8: =CONTRATTO!J8 -> 0 | U8: =CONTRATTO!K8 -> 0
H9: =F9-G9 -> 0 | J9: =F9-I9 -> 0 | L9: Proroga 4 | M9: =CONTRATTO!C9 -> 0 | N9: =CONTRATTO!D9 -> 0 | O9: =CONTRATTO!E9 -> 0 | P9: =CONTRATTO!F9 -> 0 | Q9: =CONTRATTO!G9 -> 0 | R9: =CONTRATTO!H9 -> 0 | S9: =CONTRATTO!I9 -> 0 | T9: =CONTRATTO!J9 -> 0 | U9: =CONTRATTO!K9 -> 0
H10: =F10-G10 -> 0 | J10: =F10-I10 -> 0 | L10: Proroga 5 | M10: =CONTRATTO!C10 -> 0 | N10: =CONTRATTO!D10 -> 0 | O10: =CONTRATTO!E10 -> 0 | P10: =CONTRATTO!F10 -> 0 | Q10: =CONTRATTO!G10 -> 0 | R10: =CONTRATTO!H10 -> 0 | S10: =CONTRATTO!I10 -> 0 | T10: =CONTRATTO!J10 -> 0 | U10: =CONTRATTO!K10 -> 0
H11: =F11-G11 -> 0 | J11: =F11-I11 -> 0 | L11: Proroga 6 | M11: =CONTRATTO!C11 -> 0 | N11: =CONTRATTO!D11 -> 0 | O11: =CONTRATTO!E11 -> 0 | P11: =CONTRATTO!F11 -> 0 | Q11: =CONTRATTO!G11 -> 0 | R11: =CONTRATTO!H11 -> 0 | S11: =CONTRATTO!I11 -> 0 | T11: =CONTRATTO!J11 -> 0 | U11: =CONTRATTO!K11 -> 0
H12: =F12-G12 -> 0 | J12: =F12-I12 -> 0 | L12: Proroga 7 | M12: =CONTRATTO!C12 -> 0 | N12: =CONTRATTO!D12 -> 0 | O12: =CONTRATTO!E12 -> 0 | P12: =CONTRATTO!F12 -> 0 | Q12: =CONTRATTO!G12 -> 0 | R12: =CONTRATTO!H12 -> 0 | S12: =CONTRATTO!I12 -> 0 | T12: =CONTRATTO!J12 -> 0 | U12: =CONTRATTO!K12 -> 0
H13: =F13-G13 -> 0 | J13: =F13-I13 -> 0 | L13: Proroga 8 | M13: =CONTRATTO!C13 -> 0 | N13: =CONTRATTO!D13 -> 0 | O13: =CONTRATTO!E13 -> 0 | P13: =CONTRATTO!F13 -> 0 | Q13: =CONTRATTO!G13 -> 0 | R13: =CONTRATTO!H13 -> 0 | S13: =CONTRATTO!I13 -> 0 | T13: =CONTRATTO!J13 -> 0 | U13: =CONTRATTO!K13 -> 0
H14: =F14-G14 -> 0 | J14: =F14-I14 -> 0 | L14: Proroga 9 | M14: =CONTRATTO!C14 -> 0 | N14: =CONTRATTO!D14 -> 0 | O14: =CONTRATTO!E14 -> 0 | P14: =CONTRATTO!F14 -> 0 | Q14: =CONTRATTO!G14 -> 0 | R14: =CONTRATTO!H14 -> 0 | S14: =CONTRATTO!I14 -> 0 | T14: =CONTRATTO!J14 -> 0 | U14: =CONTRATTO!K14 -> 0
H15: =F15-G15 -> 0 | J15: =F15-I15 -> 0 | L15: Proroga 10 | M15: =CONTRATTO!C15 -> 0 | N15: =CONTRATTO!D15 -> 0 | O15: =CONTRATTO!E15 -> 0 | P15: =CONTRATTO!F15 -> 0 | Q15: =CONTRATTO!G15 -> 0 | R15: =CONTRATTO!H15 -> 0 | S15: =CONTRATTO!I15 -> 0 | T15: =CONTRATTO!J15 -> 0 | U15: =CONTRATTO!K15 -> 0
F16: =SUM(F4:F15) -> 3092872 | G16: =SUM(G4:G15) -> 0 | H16: =SUM(H4:H15) -> 3092872 | I16: =SUM(I4:I15) -> 0 | J16: =SUM(J4:J15) -> 3092872 | O16: =SUM(O4:O15) -> 6873049 | Q16: =SUM(Q4:Q15) -> 6873049 | R16: =SUM(R4:R15) -> 38658 | S16: =SUM(S4:S15) -> 6834391 | T16: =SUM(T4:T15) -> 0 | U16: =SUM(U4:U15) -> 0
E18: PROIEZIONE | F18: 46387 | G18: A FINE LUGLIO | Q18: FORECAST
E19: SW approvato | F19: =SUMIFS(MEV!O:O,MEV!L:L,"approvato") -> 1586473.7 | G19: =F19 -> 1586473.7 | Q19: Mesi \ Anni | R19: 2026 | S19: 2027 | T19: 2028 | U19: 2029
E20: Presidio | F20: ='CHECK CON POSTE'!I11 -> 38658 | G20: =('CHECK CON POSTE'!C11*7)-'CHECK CON POSTE'!H11 -> 6443 | Q20: Gennaio | R20: 481265
E21: Collaudo | F21: ='CHECK CON POSTE'!I10-'CHECK CON POSTE'!F10 -> 342342 | G21: ='CHECK CON POSTE'!C10*7 -> 217854 | Q21: Febbraio | R21: 51519
E22: Checchi | F22: ='CHECK CON POSTE'!I12 -> 120000 | G22: =F22 -> 120000 | Q22: Marzo | R22: 252000
Q23: Aprile | R23: 203481.2
E24: Consuntivo | F24: =-I16 -> 0 | Q24: Maggio | R24: 197927.73
E25: FCST + Subco (certo) | F25: =-R32 -> -2477767 | G25: =-SUM(R20:R26) -> -1577767 | Q25: Giugno | R25: 204949.02
E26: FCST Subco (unknown) | F26: =0 -> 0 | Q26: Luglio | R26: 186625
E27: DEBITO VECCHIO AQ | F27: 0 | G27: =F27 -> 0 | Q27: Agosto | R27: 150000
Q28: Settembre | R28: 200000
E29: TOT. PARZIALE | F29: =SUM(F19:F28) -> -390293.28 | G29: =SUM(G19:G28) -> 353003.72 | Q29: Ottobre | R29: 200000
E30: In approvazione | F30: =SUMIFS(MEV!AD:AD,MEV!L:L,"in approvazione") -> 596992.86 | G30: =F30 -> 596992.86 | Q30: Novembre | R30: 200000
Q31: Dicembre | R31: 150000
E32: TOTALE | F32: =F29+F30 -> 206699.58 | G32: =G29+G30 -> 949996.58 | Q32: TOTALE | R32: =SUM(R20:R31) -> 2477767 | S32: =SUM(S20:S31) -> 0 | T32: =SUM(T20:T31) -> 0 | U32: =SUM(U20:U31) -> 0
D35: Revenue | E35: AQ 2022 | F35: 10230348
E36: AQ 2026 | F36: 579725.29
E37: TOT REVENUE (A) | F37: =SUM(F35:F36) -> 10810074
D39: Ordini | E39: AQ 2022 | F39: 9847797
E40: AQ 2026 - Presidio H1 | F40: =CONTRATTO!I61 -> 38658
E41: TOT ORDINI (B) | F41: =SUM(F39:F40) -> 9886455
E43: ORDINI (B) - REVENUE (A) | F43: =F41-F37 -> -923618.53
D45: ENTRATE CERTE AQ 26 | E45: Collaudo vecchia tariffa | F45: =F21 -> 342342
E46: Checchi - Q1 2026 | F46: 0 | G46: Inserito nelle iniziative approvate
E47: T&T Repo 2025 | F47: 0 | G47: Inserito nelle iniziative approvate
...

Sheet TEAM LAVORO
BB1: GENNAIO 2026 | BP1: 21 | BQ1: 4 | BT1: 12
B2: # | C2: Risorse | D2: Ambito | E2: Specialità | F2: Poste Application | G2: Note | I2: GRADE | J2: CDC | K2: Practice | L2: ADRC | M2: COR | N2: Corp ID | O2: E-mail address | P2: Certificazioni | Q2: Serial Number | R2: System name | S2: Wireless MAC | T2: Device name | U2: Processor | V2: Installed RAM | W2: Device ID | X2: Product ID | Y2: System type | Z2: Pen and touch | AA2: Edition | AB2: Version | AC2: Installed on | AD2: OS build | AE2: Experience | AF2: SEDE | AG2: Nomina autorizzato Delivery | AH2: Data ingresso | AI2: Data Uscita | AJ2: Dichiarazione uscita | AK2: IT Charter | AL2: Corso Cybersecurity | AM2: Data Corso | AN2: Zscaler (enable) | AO2: Intune Move | AP2: Utenza Poste | AQ2: IT CHART | AR2: MS Office | AS2: DL IT Poste-Intune-LogisticaLotto2 | AT2: DL IT Poste - Logistica Lotto 2 - Ticket Nodo | AU2: DL IT Cap Referenti KT | AV2: DL IT CAP Logistica | AW2: DL IT Poste-Monitoraggio-Produzione | AX2: DL IT CapVolPay Monitoraggio | AY2: Telelavoro | BB2: Previste | BC2: FCST | BD2: Reali | BE2: Differenza | BH2: ACTUAL | BI2: AZIONI | BJ2: TEMPI | BK2: ALLOCAZIONE % | BL2: TARGET | BM2: SAVING | BO2: Costo giornaliero | BP2: Costo mese | BQ2: Costo Team Actual | BR2: Aprile Approvato | BS2: Delta ad Aprile | BT2: Costo Team 31/12 | BU2: In approvazione a fine anno | BV2: Delta a fine anno
A3: x | B3: 1 | C3: Stefanelli Mauro | D3: PM | H3: STEFANELLI MAURO (D03R1) | I3: D03R1 | J3: IT01C00039 | K3: ABL_C&CA CLOUD NATIVE HS | L3: 418.09 | M3: 653.26 | N3: MSTEFANE | O3: mauro.stefanelli@capgemini.com | R3: TX4M19GQ79 | S3: bc:d0:74:a1:74:10 | T3: TX4M19GQ79 | U3: Apple M1 Pro | V3: 16,0 GB | W3: 261B129C-EAF9-5F5A-9682-6FFA748F15BC | X3: 00006000-001A19980E92401E | Y3: Sequoia 15.4.1 (24E263) | Z3: No pen or touch input is available for this display | AA3: Sequoia 15.4.1 (24E263) | AB3: 15.4.1 | AE3: MacBook Pro | AF3: Roma - Torre Spaccata | AH3: 44946 | AK3: OK | AL3: Completed | AM3: 45023 | AN3: N | AP3: CAP3FJI | AQ3: 46084 | AS3: x | AT3: x | AU3: x | AV3: x | BB3: 18 | BH3: =M3 -> 653.26 | BK3: 1 | BL3: =BH3*BK3 -> 653.26
A4: x | B4: =B3+1 -> 2 | C4: Falo' Stefano | D4: PMO | H4: FALO' STEFANO GIANLUCA (D04G1) | I4: D04G1 | J4: IT01C00080 | K4: ABL_BTS BANKING | L4: 413.89414 | M4: 646.7096 | N4: STFALO | O4: stefano.falo@capgemini.com | R4: ITLIK1710001948 | S4: 70-A8-D3-5F-26-70 | T4: LIT-5CG2191HW5 | U4: 11th Gen Intel(R) Core(TM) i5-1145G7 @ 2.60GHz 2.61 GHz | V4: 16,0 GB (15,7 GB usable) | W4: 78CDA13A-E7F6-4E2B-9703-D92A31012634 | X4: 00331-10000-00001-AA195 | Y4: 64-bit operating system, x64-based processor | Z4: No pen or touch input is available for this display | AA4: Windows 11 Pro | AB4: 23H2 | AC4: 29/‎10/‎2024 | AD4: 22631.5189 | AE4: Windows Feature Experience Pack 1000.22700.1077.0 | AF4: Milano - Pharo | AH4: 44986 | AK4: OK | AL4: Completed | AM4: 45062 | AN4: Y | AP4: CAP3J8J | AQ4: 46084 | AS4: x | AT4: x | AU4: x | AV4: x | BB4: 15 | BH4: =M4 -> 646.7096 | BK4: 1 | BL4: =BH4*BK4 -> 646.7096 | BO4: =SUM(BL3:BL4) -> 1299.9696 | BP4: =BO4*BP1 -> 27299.362 | BQ4: =BP4*BQ1 -> 109197.45 | BR4: 0 | BS4: =BR4-BQ4 -> -109197.45
A5: x | B5: =B4+1 -> 3 | C5: Fabbri Maurizio | D5: ACCETTAZIONE e PRENOTAZIONE | E5: NPSO/BEP | F5: NPSO / BEP | H5: FABBRI MAURIZIO (D04C1) | I5: D04C1 | J5: IT01C00074 | K5: ABL_DCX EXPERIENCE LEAD | L5: 401 | M5: 626.5625 | N5: MFABBRI | O5: maurizio.fabbri@capgemini.com | P5: - | Q5: 5CG2213HRQ | R5: ITLIK1710001365 | S5: 70-A8-D3-E9-75-78 | T5: ITLIK1710001365 | U5: 11th Gen Intel(R) Core(TM) i5-1145G7 @ 2.60GHz 2.61 GHz | V5: 16,0 GB (15,7 GB usable) | W5: 97D6D904-856F-471B-85E6-2B238085CEC6 | X5: 00331-10000-00001-AA777 | Y5: 64-bit operating system, x64-based processor | Z5: No pen or touch input is available for this display | AA5: Windows 11 Pro | AB5: 23H2 | AC5: 16/‎02/‎2024 | AD5: 22631.5189 | AE5: Windows Feature Experience Pack 1000.22700.1077.0 | AF5: La Spezia | AH5: 44949 | AK5: OK | AL5: Completed | AM5: 45068 | AN5: Y | AO5: 45446 | AP5: CAP3F17 | AQ5: 46086 | AS5: x | AU5: x | AV5: x | AY5: SI | BB5: 18 | BH5: =M5 -> 626.5625 | BK5: 1 | BL5: =BH5*BK5 -> 626.5625
A6: x | B6: =B5+1 -> 4 | C6: Ricciardi Giannoni Francesco | D6: ACCETTAZIONE e PRENOTAZIONE | E6: NPSO | F6: NPSO | H6: RICCIARDI GIANNONI FRANCESCO (C04O1) | I6: C04O1 | J6: IT01C00229 | K6: ABL_PBS ORACLE | L6: 295.54542 | M6: 461.78972 | N6: FRICCIAR | O6: francesco.ricciardi@capgemini.com | P6: - MongoDB Associate MongoDB Architect General English - EF Level 6 - Elementary - CEFR Level A2 Capgemini - Software Engineering | Q6: 5CG3422QPW | R6: LIT004315 | S6: BC-A8-A6-59-9C-3C | T6: ITLIK1710002954 | U6: 13th Gen Intel(R) Core(TM) i5-1345U 1.60 GHz | V6: 16,0 GB (15,6 GB utilizzabile) | W6: CE027D6E-A953-4688-AD62-303958ACDE51 | X6: 00331-10000-00001-AA532 | Y6: Sistema operativo a 64 bit, processore basato su x64 | Z6: Nessun input penna o tocco disponibile per questo schermo | AA6: Windows 11 Pro | AB6: 23H2 | AC6: ‎19/‎01/‎2024 | AD6: 22631.5189 | AE6: Pacchetto di esperienze per funzionalità Windows 1000.22700.1077.0 | AF6: La Spezia | AH6: 44942 | AK6: OK | AL6: Completed | AM6: 45062 | AN6: N | AO6: 45446 | AP6: CAP3XTV | AQ6: 46084 | AR6: NO ROLLBACK | AS6: x | AT6: x | AV6: x | BB6: 18 | BH6: =M6 -> 461.78972 | BK6: 1 | BL6: =BH6*BK6 -> 461.78972
A7: x | B7: =B6+1 -> 5 | C7: Perrotta Alessio | D7: ACCETTAZIONE e PRENOTAZIONE | E7: BEP | F7: BEP | H7: PERROTTA ALESSIO (C04C2) | I7: C04C2 | J7: IT01C00074 | K7: ABL_DCX EXPERIENCE LEAD | L7: 337 | M7: 526.5625 | N7: APERROTT | O7: alessio.perrotta@capgemini.com | P7: - Red Hat Certified specialist in openshift application development - Professional Scrum Developer I - GCP Professional Cloud Architect - GCC Professional Cloud Developer - Mongodb SI Associate Certification - Mongodb SI Architect Certification - Oracle Certified Professional, Java SE 7 Programmer - Oracle Certified Associate, Java SE 7 Programmer - Oracle Certified Expert, Java EE 6 Web Services Developer - Oracle Certified Expert, Java EE 6 Enterprise JavaBeans Developer | Q7: PF13Q0BD | R7: LIT004801 | S7: 3C-18-A0-CD-EA-53 | T7: LIT-5CG4090SHL | U7: AMD Ryzen 5 PRO 7540U w/ Radeon 740M Graphics 3.20 GHz | V7: 16,0 GB (15,3 GB usable) | W7: BC836FAB-D4B8-4CAB-8997-6CBD0C2B7271 | X7: 00331-10000-00001-AA376 | Y7: 64-bit operating system, x64-based processor | Z7: No pen or touch input is available for this display | AA7: Windows 11 Pro | AB7: 23H2 | AC7: 07/‎06/‎2024 | AD7: 22631.5189 | AE7: Windows Feature Experience Pack 1000.22700.1077.0 | AF7: Roma - Torre Spaccata | AH7: 44938 | AK7: OK | AL7: Completed | AM7: 45108 | AN7: N | AO7: ON HOLD | AP7: CAP3HJ9 | AQ7: 46084 | AS7: x | AV7: x | AY7: SI | BB7: 18 | BH7: =M7 -> 526.5625 | BK7: 1 | BL7: =BH7*BK7 -> 526.5625 | BO7: =SUM(BL5:BL7) -> 1614.9147 | BP7: =BO7*BP1 -> 33913.209 | BQ7: =BP7*BQ1 -> 135652.84 | BR7: =SUMIFS(MEV!O:O,MEV!C:C,"BEP",MEV!L:L,"approvato")+SUMIFS(MEV!O:O,MEV!C:C,"NPSO",MEV!L:L,"approvato") -> 255112.71 | BS7: =BR7-BQ7 -> 119459.87 | BT7: =BP7*BT1 -> 406958.51 | BU7: =SUMIFS(MEV!O:O,MEV!C:C,"BEP",MEV!L:L,"In approvazione")+SUMIFS(MEV!O:O,MEV!C:C,"NPSO",MEV!L:L,"In approvazione") -> 487004.38
A8: x | B8: =B7+1 -> 6 | C8: Mele Annamaria Leonarda | D8: Integrazione e TRASPORTI | E8: AFU | F8: Mediation / SAP EM | H8: MELE ANNAMARIA LEONARDA (C03T1) | I8: C03T1 | J8: IT01C00033 | K8: ABL_C&CA EM & BA | L8: 295 | M8: 460.9375 | N8: ANMELE | O8: annamaria.mele@capgemini.com | Q8: 5CG1430S76 | R8: LIT009750 | S8: 44-E5-17-29-CD-EA | T8: LIT009750 | U8: 11th Gen Intel(R) Core(TM) i5-1145G7 @ 2.60GHz 2.61 GHz | V8: 16,0 GB (15,7 GB usable) | W8: C02DA010-D7C5-4DF1-8848-EFF1409078A1 | X8: 00331-10000-00001-AA494 | Y8: 64-bit operating system, x64-based processor | Z8: No pen or touch input is available for this display | AA8: Windows 11 Pro | AB8: 23H2 | AC8: 26/‎10/‎2023 | AD8: 22631.5335 | AE8: Windows Feature Experience Pack 1000.22700.1081.0 | AF8: Roma - Torre Spaccata | AG8: 46106 | AH8: 44949 | AK8: OK | AL8: Completed | AM8: 45205 | AN8: Y | AO8: ON HOLD | AP8: DGS3ISP | AQ8: 46090 | AS8: x | AU8: x | AV8: x | BB8: 15 | BH8: =M8 -> 460.9375 | BK8: 1 | BL8: =BH8*BK8 -> 460.9375
A9: x | B9: =B8+1 -> 7 | C9: Vitale Antonio | D9: Integrazione e TRASPORTI | E9: DEV | F9: Mediation | H9: VITALE ANTONIO (A03Y5) | I9: A03Y5 | J9: IT01C00038 | K9: ABL_C&CA MICROSOFT | L9: 214 | M9: 334.375 | N9: ANTVITAL | O9: antonio.vitale@capgemini.com | Q9: 5CG2191HX8 | R9: ITLIK1710001855 | S9: 70-A8-D3-5F-25-30 | T9: ITLIK1710001855 | U9: 11th Gen Intel(R) Core(TM) i5-1145G7 @ 2.60GHz 2.61 GHz | V9: 16,0 GB (15,7 GB usable) | W9: 4F7E9B24-7821-42E1-9C62-58B60D781324 | X9: 00331-10000-00001-AA987 | Y9: 64-bit operating system, x64-based processor | Z9: No pen or touch input is available for this display | AA9: Windows 11 Pro | AB9: 23H2 | AC9: 26/‎02/‎2024 | AD9: 22631.5189 | AE9: Windows Feature Experience Pack 1000.22700.1077.0 | AF9: Roma - Torre Spaccata | AH9: 44942 | AK9: OK | AL9: Completed | AM9: 45317 | AN9: N | AO9: ON HOLD | AP9: CAP3XTY | AQ9: 46084 | AS9: x | AV9: x | AY9: SI | BB9: 18 | BH9: =M9 -> 334.375 | BK9: 1 | BL9: =BH9*BK9 -> 334.375
A10: x | B10: =B9+1 -> 8 | C10: Pistis Giulio | D10: Integrazione e TRASPORTI | E10: DEV | F10: SAP EM | H10: PISTIS GIULIO (A04Q5) | I10: A04Q5 | J10: IT01C00232 | K10: ABL_PBS SAP | L10: 219 | M10: 342.1875 | N10: GPISTIS | O10: giulio.pistis@capgemini.com | Q10: 5CG1346978 | R10: LIT5CG1346978 | S10: F4-4E-E3-2A-55-02 | T10: LIT-5CG1346978 | U10: 11th Gen Intel(R) Core(TM) i5-1145G7 @ 2.60GHz 2.61 GHz | V10: 16,0 GB (15,7 GB usable) | W10: 155EF870-BEE4-477D-A951-EDC7B013C1AD | X10: 00331-10000-00001-AA462 | Y10: 64-bit operating system, x64-based processor | Z10: No pen or touch input is available for this display | AA10: Windows 11 Pro | AB10: 23H2 | AC10: 12/‎09/‎2023 | AD10: 22631.5189 | AE10: Windows Feature Experience Pack 1000.22700.1077.0 | AF10: Roma - Aldobrandeschi | AG10: 46105 | AH10: 45359 | AK10: OK | AL10: Completed | AM10: 45108 | AN10: Y | AO10: 45435 | AP10: CAP3Y7E | AQ10: 46084 | AS10: x | AV10: x | BB10: 15 | BH10: =M10 -> 342.1875 | BK10: 1 | BL10: =BH10*BK10 -> 342.1875
A11: x | B11: =B10+1 -> 9 | C11: Pallotti Silvia | D11: Tracciatura NAZIONALE | E11: FMS - AFU | F11: FMS / SGT | H11: PALLOTTI SILVIA (A03X5) | I11: A03X5 | J11: IT01C00037 | K11: ABL_C&CA JAVA & OPENSOURCE | L11: 218 | M11: 340.625 | N11: SIPALLOT | O11: silvia.pallotti@capgemini.com | Q11: 5CG2222M17 | R11: ITLIK1710001349 | S11: 30-03-C8-95-3E-1D | T11: LIT-5CG2191JY5 | U11: 11th Gen Intel(R) Core(TM) i5-1145G7 @ 2.60GHz 2.61 GHz | V11: 16,0 GB (15,7 GB usable) | W11: 78CDA13A-E7F6-4E2B-9703-D92A31012634 | X11: 00331-10000-00001-AA244 | Y11: 64-bit operating system, x64-based processor | Z11: No pen or touch input is available for this display | AA11: Windows 11 Pro | AB11: 23H2 | AC11: ‎31/‎12/‎2024 | AD11: 22631.5189 | AE11: Windows Feature Experience Pack 1000.22700.1077.0 | AF11: Roma - Aldobrandeschi | AG11: 46106 | AH11: 45055 | AK11: OK | AL11: Completed | AM11: 45321 | AN11: N | AO11: 45433 | AP11: EXTA06Y | AQ11: 46087 | AS11: x | AV11: x | BB11: 15 | BH11: =M11 -> 340.625 | BK11: 1 | BL11: =BH11*BK11 -> 340.625
A12: x | B12: =B11+1 -> 10 | C12: Belli Filippo | D12: Tracciatura INTERNAZIONALE | E12: SGT / MAILBOX | H12: BELLI FILIPPO (A03X5) | I12: A03X5 | J12: IT01C00037 | K12: ABL_C&CA JAVA & OPENSOURCE | L12: 218 | M12: 340.625 | N12: FBELLI | O12: filippo.belli@capgemini.com | Q12: 5CG20446K5 | R12: ITLIK6066000241 | S12: F0-B6-1E-9A-C0-1D | T12: ITLIK6066000241 | U12: 11th Gen Intel(R) Core(TM) i5-1145G7 @ 2.60GHz 2.61 GHz | V12: 16,0 GB (15,7 GB usable) | W12: D0466357-D691-4284-AB0A-1E15FF1B2A04 | X12: 00331-10000-00001-AA222 | Y12: 64-bit operating system, x64-based processor | Z12: No pen or touch input is available for this display | AA12: Windows 11 Pro | AB12: 23H2 | AC12: 12/‎09/‎2023 | AD12: 22631.5189 | AE12: Windows Feature Experience Pack 1000.22700.1077.0 | AF12: Roma - Aldobrandeschi | AG12: 46106 | AH12: 45100 | AK12: OK | AL12: Completed | AM12: 45323 | AN12: N | AO12: 45448 | AP12: EXTA058 | AQ12: 46084 | AS12: x | AV12: x | BB12: 18 | BH12: =M12 -> 340.625 | BK12: 1 | BL12: =BH12*BK12 -> 340.625 | BO12: =SUM(BL8:BL12) -> 1818.75 | BP12: =BO12*BP1 -> 38193.75 | BQ12: =(1569*3)+(BP12*4) -> 157482 | BR12: =SUMIFS(MEV!O:O,MEV!C:C,"FMS",MEV!L:L,"approvato")+SUMIFS(MEV!O:O,MEV!C:C,"SGT",MEV!L:L,"approvato")+SUMIFS(MEV!O:O,MEV!C:C,"SAP LES",MEV!L:L,"approvato") -> 0 | BS12: =BR12-BQ12 -> -157482 | BT12: =BP12*BT1 -> 458325
B13: =B12+1 -> 11 | C13: Del Vecchio Gianluigi | D13: Data LAKE Tracciatura | E13: T&T Repo | F13: T&T Repo | H13: DEL VECCHIO GIANLUIGI (D09U1) | I13: D09U1 | J13: IT01C00162 | K13: ABL_ID_PRACTICE | L13: 460 | N13: GDELVECC | O13: gianluigi.delvecchio@capgemini.com | P13: - AWS Certified Solutions Architect – Associate - CDP Certified Generalist - L1 Certified Architect (certificazione interna Capgemini) - HDP Certified Developer | Q13: 5CG3376166 | R13: ITLIK1710002691 | S13: 40-1A-58-8B-FC-3A | T13: ITLIK1710002691 | U13: AMD Ryzen 5 PRO 7540U w/ Radeon 740M Graphics 3.20 GHz | V13: 16,0 GB (15,3 GB usable) | W13: CE027D6E-A953-4688-AD62-303958ACDE51 | X13: 00331-10000-00001-AA281 | Y13: 64-bit operating system, x64-based processor | Z13: No pen or touch input is available for this display | AA13: Windows 11 Pro | AD13: 22631.5189 | AE13: Pacchetto di esperienze per funzionalità Windows 1000.22700.1077.0 | AF13: Roma - Torre Spaccata | AH13: 44942 | AK13: OK | AL13: Completed | AM13: 45144 | AN13: Y | AO13: ON HOLD | AP13: CAP3RR0 | AS13: x | AT13: x | AU13: x | AV13: x | BB13: 18 | BH13: =M13 -> 0 | BK13: 1 | BL13: =BH13*BK13 -> 0
A14: x | B14: =B13+1 -> 12 | C14: Mallamaci Riccardo Francesco | D14: Data LAKE Tracciatura | E14: T&T Repo | F14: T&T Repo | H14: MALLAMACI RICCARDO FRANCESCO (C03X1) | I14: C03X1 | J14: IT01C00037 | K14: ABL_C&CA JAVA & OPENSOURCE | L14: 298 | N14: RMALLAMA | O14: riccardo.mallamaci@capgemini.com | P14: -AWS Certified Developer – Associate -AWS Certified Solutions Architect – Associate | Q14: 5CG3376183 | R14: ITLIK1710002659 | S14: 40-1A-58-8B-E5-D0 | T14: ITLIK1710002659 | U14: AMD Ryzen 5 PRO 7540U w/ Radeon 740M Graphics 3.20 GHz | V14: 16,0 GB (15,3 GB utilizzabile) | W14: CE027D6E-A953-4688-AD62-303958ACDE51 | X14: 00331-10000-00001-AA274 | Y14: Sistema operativo a 64 bit, processore basato su x64 | Z14: Nessun input penna o tocco disponibile per questo schermo | AA14: Windows 11 Pro | AB14: 23H2 | AC14: 04/‎12/‎2023 | AD14: 22631.5189 | AE14: Pacchetto di esperienze per funzionalità Windows 1000.22700.1077.0 | AF14: Milano - Pharo | AH14: 44942 | AK14: OK | AL14: Completed | AM14: 45092 | AN14: N | AO14: 45436 | AP14: CAP3RD6 | AS14: x | AV14: x | AY14: SI | BB14: 18 | BH14: =M14 -> 0 | BK14: 1 | BL14: =BH14*BK14 -> 0
A15: x | B15: =B14+1 -> 13 | C15: Steriti Maria Felicia | D15: Data LAKE Tracciatura | E15: T&T Repo | F15: T&T Repo | H15: STERITI MARIA FELICIA (C09U1) | I15: C09U1 | J15: IT01C00162 | K15: ABL_ID_PRACTICE | L15: 317.00299 | N15: MSTERITI | O15: maria.steriti@capgemini.com | Q15: 5CG2191JXM | R15: ITLIK1710001771 | S15: 70-A8-D3-5F-24-EA | T15: ITLIK1710001771 | U15: 11th Gen Intel(R) Core(TM) i5-1145G7 @ 2.60GHz 2.61 GHz | V15: 16,0 GB (15,7 GB usable) | W15: F67EC850-5ADA-497D-9F53-D21D1EA8346D | X15: 00331-10000-00001-AA389 | Y15: 64-bit operating system, x64-based processor | Z15: No pen or touch input is available for this display | AA15: Windows 11 Pro | AB15: 23H2 | AC15: ‎20/‎03/‎2024 | AD15: 22631.5189 | AE15: Windows Feature Experience Pack 1000.22700.1077.0 | AF15: Roma - Torre Spaccata | AH15: 44942 | AK15: OK | AL15: Completed | AM15: 45316 | AN15: N | AO15: 45434 | AP15: CAP3XTX | AS15: x | AT15: x | AV15: x | AY15: SI | BB15: 18 | BH15: =M15 -> 0 | BK15: 1 | BL15: =BH15*BK15 -> 0
B16: =B15+1 -> 14 | C16: Tomo Davide | D16: Data LAKE Tracciatura | E16: T&T Repo | F16: T&T Repo | H16: TOMO DAVIDE (A03X5) | I16: A03X5 | J16: IT01C00037 | K16: ABL_C&CA JAVA & OPENSOURCE | L16: 218 | N16: DATOMO | O16: davide.tomo@capgemini.com | Q16: H2W64M3 | R16: ITLIK1710000274 | S16: 20-C1-9B-BF-E3-4D | T16: ITLIK1710000274 | U16: 11th Gen Intel(R) Core(TM) i5-1145G7 @ 2.60GHz 1.50 GHz | V16: 16,0 GB (15,4 GB utilizzabile) | W16: CE027D6E-A953-4688-AD62-303958ACDE51 | X16: 00331-10000-00001-AA202 | Y16: Sistema operativo a 64 bit, processore basato su x64 | Z16: Nessun input penna o tocco disponibile per questo schermo | AA16: Windows 11 Pro | AB16: 23H2 | AC16: 24/‎01/‎2024 | AD16: 22631.5189 | AE16: Pacchetto di esperienze per funzionalità Windows 1000.22700.1077.0 | AF16: Roma - Torre Spaccata | AH16: 45194 | AK16: OK | AL16: Completed | AM16: 45195 | AN16: N | AO16: 45436 | AP16: EXTA1RF | AS16: x | AV16: x | AY16: SI | BB16: 18 | BH16: =M16 -> 0 | BK16: 1 | BL16: =BH16*BK16 -> 0
A17: x | B17: =B16+1 -> 15 | C17: Grazioli Alessio | D17: Data LAKE Tracciatura | E17: T&T Repo | F17: T&T Repo | H17: GRAZIOLI ALESSIO (C09U1) | I17: C09U1 | J17: IT01C00162 | K17: ABL_ID_PRACTICE | L17: 317.00299 | N17: ALGRAZIO | O17: alessio.grazioli@capgemini.com | P17: -Confluent Certified Developer for Apache Kafka | Q17: 5CG3422PCK | R17: ITLIK1710002868 | S17: 90-65-84-8B-D8-5F | T17: ITLIK1710002868 | U17: 13th Gen Intel(R) Core(TM) i5-1345U 1.60 GHz | V17: 16,0 GB (15,6 GB utilizzabile) | W17: CE027D6E-A953-4688-AD62-303958ACDE51 | X17: 00331-10000-00001-AA837 | Y17: Sistema operativo a 64 bit, processore basato su x64 | Z17: Nessun input penna o tocco disponibile per questo schermo | AA17: Windows 11 Pro | AB17: 23H2 | AC17: 06/‎12/‎2023 | AD17: 22631.5189 | AE17: Pacchetto di esperienze per funzionalità Windows 1000.22700.1077.0 | AF17: Roma - Torre Spaccata | AH17: 45260 | AK17: OK | AL17: Completed | AM17: 45287 | AN17: N | AO17: 45434 | AP17: FIN3FG0 | AS17: x | AV17: x | BB17: 18 | BH17: =M17 -> 0 | BK17: 1 | BL17: =BH17*BK17 -> 0 | BO17: =SUM(BL13:BL17) -> 0 | BP17: =BO17*BP1 -> 0 | BQ17: =BP17*BQ1 -> 0
A18: x | B18: =B17+1 -> 16 | C18: De Santis Dario | D18: Tracciatura INTERNAZIONALE | E18: ILP | F18: ILP / IPER / IPER SUITE / SCO | H18: DE SANTIS DARIO (C03X2) | I18: C03X2 | J18: IT01C00037 | K18: ABL_C&CA JAVA & OPENSOURCE | L18: 338 | M18: 528.125 | N18: DARDESAN | O18: dario.de-santis@capgemini.com | P18: - Certified Kubernetes Application Developer Redis Certified Developer MongoDB Certified Developer Associate Level MongoDB SI Associate MongoDB SI Architect '- AWS Partner : Generative AI Essentials (Business) - Oracle Certified Associate, Java SE 7 Programmer - Oracle Certified Professional, Java SE 7 Programmer - Oracle Certified Expert, Java EE 6 Web Component Developer - Oracle Certified Expert, Java EE 6 Web Services Developer - Oracle Certified Expert, Java EE 6 Persistence API Developer - Oracle Cloud Infrastructure 2021 Certified Architect Associate | Q18: 5CG3465Q50 | R18: ITLIK1710003140 | S18: 40-1A-58-C2-C5-D1 | T18: ITLIK1710003140 | U18: AMD Ryzen 5 PRO 7540U w/ Radeon 740M Graphics 3.20 GHz | V18: 16.0 GB (15.3 GB usable) | W18: CE027D6E-A953-4688-AD62-303958ACDE51 | X18: 00331-10000-00001-AA765 | Y18: 64-bit operating system, x64-based processor | Z18: No pen or touch input is available for this display | AA18: Windows 11 Pro | AB18: 23H2 | AC18: 1/‎18/‎2024 | AD18: 22631.5189 | AE18: Windows Feature Experience Pack 1000.22700.1077.0 | AF18: Roma - Torre Spaccata | AH18: 45293 | AK18: OK | AL18: Completed | AM18: 45295 | AN18: N | AO18: 45442 | AP18: EGN3FM9 | AQ18: 46084 | AS18: x | AV18: x | BB18: 18 | BH18: =M18 -> 528.125 | BK18: 1 | BL18: =BH18*BK18 -> 528.125
A19: x | B19: =B18+1 -> 17 | C19: Cuozzo Maddalena | D19: Tracciatura INTERNAZIONALE | F19: ILP / IPER / IPER SUITE / SCO | H19: CUOZZO MADDALENA (C03T1) | I19: C03T1 | J19: IT01C00033 | K19: ABL_C&CA EM & BA | L19: 295 | M19: 460.9375 | N19: MACUOZZO | O19: maddalena.cuozzo@capgemini.com | P19: - L'ISTQB® Certified Tester - livello FOUNDATION | Q19: 5CG1334PSH | R19: 5CG1334PSH | S19: 58-6C-25-2D-9D-E4 | T19: LIT-5CG1334PSH | U19: 11th Gen Intel(R) Core(TM) i5-1145G7 @ 2.60GHz 2.61 GHz | V19: 16,0 GB (15,7 GB usable) | W19: A9A9FF9F-69DC-46BC-80B7-AA902B0595AB | X19: 00330-53833-99315-AAOEM | Y19: 64-bit operating system, x64-based processor | Z19: No pen or touch input is available for this display | AA19: Windows 11 Pro | AB19: 23H2 | AC19: 21/‎03/‎2024 | AD19: 22631.5189 | AE19: Windows Feature Experience Pack 1000.22700.1077.0 | AF19: Roma - Aldobrandeschi | AH19: 45040 | AK19: OK | AL19: Completed | AM19: 45187 | AN19: Y | AO19: 45442 | AP19: ELS359S | AQ19: 46084 | AR19: 45460 | AS19: x | AU19: x | AV19: x | BB19: 18 | BH19: =M19 -> 460.9375 | BK19: 1 | BL19: =BH19*BK19 -> 460.9375
A20: x | B20: =B19+1 -> 18 | C20: Di Palma Marco | D20: Tracciatura INTERNAZIONALE | E20: IPER Suite + ILP | F20: ILP / IPER / IPER SUITE / SCO | H20: DI PALMA MARCO (A03X5) | I20: A03X5 | J20: IT01C00037 | K20: ABL_C&CA JAVA & OPENSOURCE | L20: 218 | M20: 340.625 | N20: MADIPALM | O20: marco.di-palma@capgemini.com | Q20: 5CG20446V1 | R20: ITLIK6066000884 | S20: F0-57-A6-AD-71-FE | T20: ITLIK6066000884 | U20: 11th Gen Intel(R) Core(TM) i5-1145G7 @ 2.60GHz 2.61 GHz | V20: 16,0 GB (15,7 GB usable) | W20: 8121E14E-319B-4783-9226-87F425C1FB56 | X20: 00330-80000-00000-AA841 | Y20: 64-bit operating system, x64-based processor | Z20: No pen or touch input is available for this display | AA20: Windows 11 Pro | AB20: 24H2 | AC20: 06/‎03/‎2025 | AD20: 26100.3775 | AE20: Windows Feature Experience Pack 1000.26100.66.0 | AF20: Roma - Torre Spaccata | AH20: 44949 | AK20: OK | AL20: Completed | AM20: 45084 | AN20: N | AO20: 45443 | AP20: CAP3VTX | AQ20: 46084 | AS20: x | AV20: x | BB20: 18 | BH20: =M20 -> 340.625 | BK20: 1 | BL20: =BH20*BK20 -> 340.625
A21: x | B21: =B20+1 -> 19 | C21: TEPI FRANCK LUDOVIC | D21: Tracciatura INTERNAZIONALE | E21: FE + BE -> ILP + Sorting Controller | F21: ILP / IPER / IPER SUITE / SCO | H21: TEPI FRANCK LUDOVIC (B03X1) | I21: B03X1 | J21: IT01C00037 | K21: ABL_C&CA JAVA & OPENSOURCE | L21: 248 | M21: 387.5 | N21: FRLTEPI | O21: franckludovic.tepi2@capgemini.com | Q21: 5CG204445S | R21: ITLIK6066000762 | S21: F0-B6-1E-A5-3B-C4 | T21: ITLIK6066000762 | U21: 11th Gen Intel(R) Core(TM) i5-1145G7 @ 2.60GHz 2.61 GHz | V21: 16,0 GB (15,7 GB utilizzabile) | W21: CE027D6E-A953-4688-AD62-303958ACDE51 | X21: 00331-10000-00001-AA131 | Y21: Sistema operativo a 64 bit, processore basato su x64 | Z21: Nessun input penna o tocco disponibile per questo schermo | AA21: Windows 11 Pro | AB21: 23H2 | AC21: 13/‎09/‎2023 | AD21: 22631.5189 | AE21: Pacchetto di esperienze per funzionalità Windows 1000.22700.1077.0 | AF21: Torino - Drosso | AH21: 45078 | AK21: OK | AL21: Completed | AM21: 45089 | AN21: N | AO21: 45443 | AP21: EXTA0JE | AQ21: 46084 | AS21: x | AV21: x | BB21: 18 | BH21: =M21 -> 387.5 | BK21: 1 | BL21: =BH21*BK21 -> 387.5 | BO21: =SUM(BL18:BL21) -> 1717.1875 | BP21: =BO21*BP1 -> 36060.938 | BQ21: =BP21*BQ1 -> 144243.75 | BR21: =SUMIFS(MEV!O:O,MEV!C:C,"ILP",MEV!L:L,"approvato")+SUMIFS(MEV!O:O,MEV!C:C,"WIPI",MEV!L:L,"approvato")+SUMIFS(MEV!O:O,MEV!C:C,"IPER_IPERSUITE",MEV!L:L,"approvato") -> 351253.53 | BS21: =BR21-BQ21 -> 207009.78 | BT21: =BP21*BT1 -> 432731.25
A22: x | B22: =B21+1 -> 20 | C22: Ferrentino Tatiana | D22: Collaudo | E22: NPSO e T&T (inizio) | F22: NPSO / T&T | H22: FERRENTINO TATIANA (A03T5) | I22: A03T5 | J22: IT01C00033 | K22: ABL_C&CA EM & BA | L22: 220 | M22: 343.75 | N22: TFERRENT | O22: tatiana.ferrentino@capgemini.com | Q22: 5CG90901QG | R22: LIT006112 | S22: D8-F2-CA-9B-53-43 | T22: LIT006112 | U22: Intel(R) Core(TM) i5-8350U CPU @ 1.70GHz 1.90 GHz | V22: 8,00 GB (7,85 GB usable) | W22: DE6014C5-E72B-40B2-9B63-D99D81B6B5DD | X22: 00331-10000-00001-AA967 | Y22: 64-bit operating system, x64-based processor | Z22: No pen or touch input is available for this display | AA22: Windows 11 Pro | AB22: 23H2 | AC22: 12/‎03/‎2024 | AD22: 22631.5335 | AE22: Windows Feature Experience Pack 1000.22700.1081.0 | AF22: Roma - Torre Spaccata | AH22: 44977 | AK22: OK | AL22: Completed | AM22: 45232 | AN22: N | AO22: 45441 | AP22: DGS3FYO | AQ22: 46085 | AS22: x | AV22: x | AY22: SI | BB22: 15 | BH22: =M22 -> 343.75 | BK22: 1 | BL22: =BH22*BK22 -> 343.75
A23: x | B23: =B22+1 -> 21 | C23: Romondini Emiliano | D23: Collaudo | E23: T&T + silk | F23: T&T | H23: ROMONDINI EMILIANO (A04S5) | I23: A04S5 | J23: IT01C00285 | K23: ABL_TES TESTING | L23: 214 | M23: 334.375 | N23: EROMONDI | O23: emiliano.romondini@capgemini.com | Q23: 5CG2205TB4 | R23: ITLIK1710001180 | S23: 30-03-C8-41-2D-4C | T23: ITLIK1710001180 | U23: AMD Ryzen 5 PRO 5650U with Radeon Graphics 2.30 GHz | V23: 16,0 GB (15,3 GB utilizzabile) | W23: CE027D6E-A953-4688-AD62-303958ACDE51 | X23: 00331-10000-00001-AA649 | Y23: Sistema operativo a 64 bit, processore basato su x64 | Z23: Nessun input penna o tocco disponibile per questo schermo | AA23: Windows 11 Pro | AB23: 23H2 | AC23: 11/‎10/‎2023 | AD23: 22631.5189 | AE23: Pacchetto di esperienze per funzionalità Windows 1000.22700.1077.0 | AF23: Roma - Torre Spaccata | AH23: 44977 | AK23: OK | AL23: Completed | AM23: 45051 | AN23: N | AO23: 45439 | AP23: TIY34ZY | AQ23: 46084 | AS23: x | AV23: x | BB23: 18 | BH23: =M23 -> 334.375 | BK23: 1 | BL23: =BH23*BK23 -> 334.375
B24: =B23+1 -> 22 | C24: Palladini Giulio | D24: Collaudo | E24: T&T, Tracciatura grandi clienti, palmare e SDA vs Palmare | F24: T&T | H24: PALLADINI GIULIO (A04S5) | I24: A04S5 | J24: IT01C00285 | K24: ABL_TES TESTING | L24: 214 | M24: 334.375 | N24: GIPALLAD | O24: giulio.palladini@capgemini.com | Q24: 5CG93671J7 | R24: LIT5CG93671J7 | S24: 50-EB-71-8F-0D-90 | T24: lit-5cg93671j7 | U24: Intel(R) Core(TM) i5-8365U CPU @ 1.60GHz 1.90 GHz | V24: 8,00 GB (7,81 GB utilizzabile) | W24: CE027D6E-A953-4688-AD62-303958ACDE51 | X24: 00331-10000-00001-AA499 | Y24: Sistema operativo a 64 bit, processore basato su x64 | Z24: Nessun input penna o tocco disponibile per questo schermo | AA24: Windows 11 Pro | AB24: 24H2 | AC24: 08/‎04/‎2025 | AD24: 26100.4061 | AE24: Pacchetto di esperienze per funzionalità Windows 1000.26100.84.0 | AF24: Roma - Torre Spaccata | AH24: 44977 | AK24: OK | AL24: Completed | AM24: 45317 | AN24: N | AO24: 45439 | AP24: fin3era | AQ24: 46084 | AS24: x | AV24: x | AY24: SI | BB24: 18 | BH24: =M24 -> 334.375 | BK24: 1 | BL24: =BH24*BK24 -> 334.375
A25: x | B25: =B24+1 -> 23 | C25: Curiel Danilo | D25: Collaudo | E25: internazione (SP1 , Iper, Iper suite e ILP) | F25: ILP / IPER / IPER SUITE / SCO | H25: CURIEL DANILO (B04S1) | I25: B04S1 | J25: IT01C00285 | K25: ABL_TES TESTING | L25: 241 | M25: 376.5625 | N25: DANCURIE | O25: danilo.curiel@capgemini.com | Q25: 5CG2044428 | R25: ITLIK6066001140 | S25: F0-B6-1E-9D-70-15 | T25: ITLIK6066001140 | U25: 11th Gen Intel(R) Core(TM) i5-1145G7 @ 2.60GHz 2.61 GHz | V25: 16,0 GB (15,7 GB utilizzabile) | W25: CE027D6E-A953-4688-AD62-303958ACDE51 | X25: 00331-10000-00001-AA244 | Y25: Sistema operativo a 64 bit, processore basato su x64 | Z25: Nessun input penna o tocco disponibile per questo schermo | AA25: Windows 11 Pro | AB25: 23H2 | AC25: 12/‎09/‎2023 | AD25: 22631.5189 | AE25: Pacchetto di esperienze per funzionalità Windows 1000.22700.1077.0 | AF25: Roma - Torre Spaccata | AH25: 44977 | AK25: OK | AL25: Completed | AM25: 45183 | AN25: N | AO25: 45440 | AP25: TOP3EUB | AQ25: 46084 | AS25: x | AV25: x | AY25: SI | BB25: 18 | BH25: =M25 -> 376.5625 | BK25: 1 | BL25: =BH25*BK25 -> 376.5625
A26: x | B26: =B25+1 -> 24 | C26: Abrami Pietro | D26: Collaudo | E26: T&T Repo, WFM e SAD e consolidatore | F26: Nodo | H26: ABRAMI PIETRO (B04S1) | I26: B04S1 | J26: IT01C00285 | K26: ABL_TES TESTING | L26: 241 | M26: 376.5625 | N26: PABRAMI | O26: pietro.abrami@capgemini.com | Q26: 5CG2205TBP | R26: ITLIK1710001161 | S26: 30-03-C8-41-10-13 | T26: ITLIK1710001161 | U26: AMD Ryzen 5 PRO 5650U with Radeon Graphics 2.30 GHz | V26: 16,0 GB (15,3 GB utilizzabile) | W26: CE87586B-165B-4C8E-9F8D-DCB487835394 | X26: 00331-10000-00001-AA874 | Y26: Sistema operativo a 64 bit, processore basato su x64 | Z26: Nessun input penna o tocco disponibile per questo schermo | AA26: Windows 11 Pro | AB26: 23H2 | AC26: 16/‎02/‎2024 | AD26: 22631.5189 | AE26: Pacchetto di esperienze per funzionalità Windows 1000.22700.1077.0 | AF26: Roma - Torre Spaccata | AH26: 44977 | AK26: OK | AL26: Completed | AM26: 45316 | AN26: N | AO26: 45440 | AP26: etm36rp | AQ26: 46084 | AS26: x | AV26: x | AY26: SI | BB26: 18 | BH26: =M26 -> 376.5625 | BK26: 1 | BL26: =BH26*BK26 -> 376.5625
B27: =B26+1 -> 25 | C27: Testoni Gianluca | D27: Collaudo | F27: T&T | M27: 275 | AK27: OK | AL27: Completed | BB27: #N/A | BH27: =M27 -> 275 | BK27: 1 | BL27: =BH27*BK27 -> 275 | BO27: =SUM(BL22:BL27) -> 2040.625 | BP27: =BO27*BP1 -> 42853.125 | BQ27: =BP27*BQ1 -> 171412.5 | BR27: =240*6*20*4 -> 115200 | BS27: =BR27-BQ27 -> -56212.5
A28: x | B28: =B27+1 -> 26 | C28: Corteselli Vincenzo | D28: Certificazione | E28: Certificazione | H28: CORTESELLI VINCENZO (C03S1) | I28: C03S1 | J28: IT01C00032 | K28: ABL_C&CA DEVOPS & PLATFORM | L28: 298 | N28: VCORTESE | T28: LIT-5CG1469DDD | U28: 11th Gen Intel(R) Core(TM) i5-1145G7 @ 2.60GHz 2.61 GHz | V28: 16,0 GB (15,7 GB utilizzabile) | W28: A6E4BCC0-7734-40EC-88CE-4C4B45C75CF0 | X28: 00330-54061-97900-AAOEM | Y28: Sistema operativo a 64 bit, processore basato su x64 | Z28: Nessun input penna o tocco disponibile per questo schermo | AA28: Windows 11 Pro | AB28: 24H2 | AC28: ‎05/‎03/‎2025 | AD28: 26100.3775 | AE28: Pacchetto di esperienze per funzionalità Windows 1000.26100.66.0 | AP28: act3ib3 | BB28: #N/A | BH28: =M28 -> 0 | BI28: Condivisione | BJ28: 45751 | BK28: 0 | BL28: =BH28*BK28 -> 0 | BO28: =BH28 -> 0 | BP28: =BH28*BP1 -> 0 | BQ28: =BP28*4 -> 0
M29: =SUM(M3:M28)*20 -> 169828.94 | BB29: =SUBTOTAL(9,BB3:BB28) -> 15 | BC29: =SUBTOTAL(9,BC3:BC28) -> 0 | BD29: =SUBTOTAL(9,BD3:BD28) -> 0 | BE29: =SUBTOTAL(9,BE3:BE28) -> 0
M30: =M29/20 -> 8491.4468 | BG30: Tariffa giornalera | BH30: =SUM(BH3:BH28) -> 8491.4468 | BL30: =SUM(BL3:BL28) -> 8491.4468 | BM30: =BH30-BL30 -> 0 | BN30: =BM30/BH30 -> 0 | BP30: =SUM(BP3:BP28) -> 178320.38 | BQ30: =SUM(BQ3:BQ28) -> 717988.53 | BS30: =SUM(BS4:BS29) -> 3577.7069 | BV30: =BU30-BQ30 -> -717988.53
BG31: Tariffa mensile (20 gg) | BH31: =BH30*20 -> 169828.94 | BL31: =BL30*20 -> 169828.94 | BM31: =BH31-BL31 -> 0 | BN31: =BM31/BH31 -> 0 | BV31: -80000 | BW31: spostamento di release
B32: DESTAFFING | BV32: =SUM(BV30:BV31) -> -797988.53
C33: Cerbone Giuseppe | G33: Rilascio il 17/07/23 | N33: Rimosso da Teams | AI33: 45124 | AK33: ok | BK33: Collaudo | BL33: 31122
C34: Giannelli Riccardo | D34: Fabbri | E34: AFU Fabbri - Sharabile | G34: Paolo Lamanna dal 09/10/23 | I34: BAM1 | M34: 366 | N34: Rimosso da Teams | AI34: 45208 | AK34: ok | BK34: Presidio | BL34: 11155
C35: Febbraro Antonio | D35: Fabbri | E35: AFU Fabbri (lavora x Divise) | G35: Paolo Lamanna dal 09/10/23 | I35: AAL2 | M35: 317 | N35: Rimosso da Teams | AI35: 45208 | AK35: ok | BL35: =BL31-BL33-BL34 -> 127551.94

Sheet SUBCO
B2: SUB-APPALTO | H2: CONSUMO | L2: ACCORDO TM (€/gg)
B3: SOCIETA' | C3: DATA RICHIESTA | D3: DATA APPROVAZIONE | E3: IMPORTO | F3: RESIDUO | H3: TASK | I3: TM | J3: TOTALE | L3: RISORSA | M3: IMPORTO
B4: Logica Informatica S.r.L. | H4: =SUMIFS(MEV!M:M,MEV!AK:AK,"Logica Informatica S.r.L.",MEV!L:L,"Approvato") -> 0 | I4: =D26 -> 0 | J4: =H4+I4 -> 0 | L4: Testoni | M4: 220
B5: Levia HUB S.p.A. | H5: =SUMIFS(MEV!M:M,MEV!AK:AK,"Levia HUB S.p.A.",MEV!L:L,"Approvato") -> 82448.46 | I5: 0 | J5: =H5+I5 -> 82448.46 | M5: 0
B6: GPA Gruppo Progetti Avanzati SRL | H6: =SUMIFS(MEV!M:M,MEV!AK:AK,"GPA Gruppo Progetti Avanzati SRL",MEV!L:L,"Approvato") -> 0 | I6: 0 | J6: =H6+I6 -> 0 | M6: 0
B7: Intent S.p.A.
M8: 0
B9: TOTALE | E9: =SUM(E4:E8) -> 0 | F9: =SUM(F4:F8) -> 0 | H9: =SUM(H4:H8) -> 82448.46 | I9: =SUM(I4:I8) -> 0 | J9: =SUM(J4:J8) -> 82448.46 | M9: =SUM(M4:M8) -> 220
B12: TESTONI 2026
B13: Mesi | C13: N° (GG) | D13: IMPORTO
B14: Gennaio | D14: =C14*$M$4 -> 0
B15: Febbraio | D15: =C15*$M$4 -> 0
B16: Marzo | D16: =C16*$M$4 -> 0
B17: Aprile | D17: =C17*$M$4 -> 0
B18: Maggio | D18: =C18*$M$4 -> 0
B19: Giugno | D19: =C19*$M$4 -> 0
B20: Luglio | D20: =C20*$M$4 -> 0
B21: Agosto | D21: =C21*$M$4 -> 0
B22: Settembre | D22: =C22*$M$4 -> 0
B23: Ottobre | D23: =C23*$M$4 -> 0
B24: Novembre | D24: =C24*$M$4 -> 0
B25: Dicembre | D25: =C25*$M$4 -> 0
B26: TOTALE | D26: =SUM(D14:D25) -> 0

Sheet CONTRATTO
B2: CONTRATTO | M2: ADEMPIMENTI
B3: Tipo Contratto | C3: RIF. Contratto | D3: Data | E3: Imp. Lordo | F3: Sconto | G3: Importo Netto | H3: Ordinato | I3: Da Ordinare | J3: Avanzato | K3: Da avanzare | M3: Costituzione Team | N3: Team Lavoro | O3: Resp. Fornitore
B4: BASE | C4: 4490015980 | D4: 46036 | E4: 6873049 | F4: 0 | G4: =E4*(1-F4) -> 6873049 | H4: =SUMIFS(CONTRATTO!I20:I60,C20:C60,"BASE") -> 38658 | I4: =G4-H4 -> 6834391 | J4: =SUMIFS(CONTRATTO!J20:J60,B20:B60,"BASE") -> 0
B5: QDO | F5: 0 | G5: =E5*(1-F5) -> 0 | H5: =SUMIFS(CONTRATTO!I20:I60,C20:C60,"QDO") -> 0 | I5: =G5-H5 -> 0 | J5: =SUMIFS(CONTRATTO!J20:J60,B20:B60,"QDO") -> 0
B6: Proroga 1 | F6: 0 | G6: =E6*(1-F6) -> 0 | H6: =SUMIFS(CONTRATTO!I20:I60,C20:C60,"Proroga 1") -> 0 | I6: =G6-H6 -> 0 | J6: =SUMIFS(CONTRATTO!J20:J60,B20:B60,"Proroga 1") -> 0
B7: Proroga 2 | F7: 0 | G7: =E7*(1-F7) -> 0 | H7: =SUMIFS(CONTRATTO!I20:I60,C20:C60,"Proroga 2") -> 0 | I7: =G7-H7 -> 0 | J7: =SUMIFS(CONTRATTO!J20:J60,B20:B60,"Proroga 2") -> 0
B8: Proroga 3 | F8: 0 | G8: =E8*(1-F8) -> 0 | H8: =SUMIFS(CONTRATTO!I20:I60,C20:C60,"Proroga 3") -> 0 | I8: =G8-H8 -> 0 | J8: =SUMIFS(CONTRATTO!J20:J60,B20:B60,"Proroga 3") -> 0
B9: Proroga 4 | F9: 0 | G9: =E9*(1-F9) -> 0 | H9: =SUMIFS(CONTRATTO!I20:I60,C20:C60,"Proroga 4") -> 0 | I9: =G9-H9 -> 0 | J9: =SUMIFS(CONTRATTO!J20:J60,B20:B60,"Proroga 4") -> 0
B10: Proroga 5 | F10: 0 | G10: =E10*(1-F10) -> 0 | H10: =SUMIFS(CONTRATTO!I20:I60,C20:C60,"Proroga 5") -> 0 | I10: =G10-H10 -> 0 | J10: =SUMIFS(CONTRATTO!J20:J60,B20:B60,"Proroga 5") -> 0
B11: Proroga 6 | F11: 0 | G11: =E11*(1-F11) -> 0 | H11: =SUMIFS(CONTRATTO!I20:I60,C20:C60,"Proroga 6") -> 0 | I11: =G11-H11 -> 0 | J11: =SUMIFS(CONTRATTO!J20:J60,B20:B60,"Proroga 6") -> 0
B12: Proroga 7 | F12: 0 | G12: =E12*(1-F12) -> 0 | H12: =SUMIFS(CONTRATTO!I20:I60,C20:C60,"Proroga 7") -> 0 | I12: =G12-H12 -> 0 | J12: =SUMIFS(CONTRATTO!J20:J60,B20:B60,"Proroga 7") -> 0
B13: Proroga 8 | F13: 0 | G13: =E13*(1-F13) -> 0 | H13: =SUMIFS(CONTRATTO!I20:I60,C20:C60,"Proroga 8") -> 0 | I13: =G13-H13 -> 0 | J13: =SUMIFS(CONTRATTO!J20:J60,B20:B60,"Proroga 8") -> 0
B14: Proroga 9 | F14: 0 | G14: =E14*(1-F14) -> 0 | H14: =SUMIFS(CONTRATTO!I20:I60,C20:C60,"Proroga 9") -> 0 | I14: =G14-H14 -> 0 | J14: =SUMIFS(CONTRATTO!J20:J60,B20:B60,"Proroga 9") -> 0
B15: Proroga 10 | F15: 0 | G15: =E15*(1-F15) -> 0 | H15: =SUMIFS(CONTRATTO!I20:I60,C20:C60,"Proroga 10") -> 0 | I15: =G15-H15 -> 0 | J15: =SUMIFS(CONTRATTO!J20:J60,B20:B60,"Proroga 10") -> 0
E16: =SUM(E4:E15) -> 6873049 | G16: =SUM(G4:G15) -> 6873049 | H16: =SUM(H4:H15) -> 38658 | I16: =SUM(I4:I15) -> 6834391
B18: BUONI DI CONSEGNA (ordinato) | M18: VERBALE ACCETTAZIONE | Q18: FATTURA
B19: ODA | C19: Contratto | D19: Data | E19: AT_ID | F19: N° RDA | G19: C.I.G. | H19: Rif. Contratto | I19: Importo | J19: Avanzato | K19: Da avanzare | M19: Mese | N19: Importo | O19: BC Rif | Q19: Numero | R19: Data | S19: Importo
B20: 4100689952 | C20: BASE | D20: 46091 | E20: 2026_1342 | F20: 1000262408 | G20: - | H20: 4490015980 | I20: 38658 | M20: 46113 | N20: 19329 | O20: 4100689952 | Q20: ITA0036670 | R20: 46141 | S20: 19329
I61: =SUM(I20:I60) -> 38658 | J61: =SUM(J20:J60) -> 0 | K61: =SUM(K20:K60) -> 0 | N61: =SUM(N20:N60) -> 19329 | S61: =SUM(S20:S60) -> 19329
C62: Differenza con approvato | I62: ='COMMESSE E FCST'!F19-I61 -> 1547815.7 | M62: Da avanzare | N62: =N61-I61 -> -19329 | S62: =N61-S61 -> 0
B67: MONITORAGGIO TOW
Y68: P. OFFERTO REALIZZAZIONE | AC68: PREZZO OFFERTO MODIFICA | AG68: TOTALE
C69: BASE | V69: ID | W69: Ambito driver | X69: Nome Driver | Y69: Semplice | Z69: Medio | AA69: Complesso | AC69: Pz. Semplice | AD69: Pz. Medio | AE69: Pz. Complesso
C70: TOW Contratto | D70: Valore Unitario | E70: Valore Totale | F70: Approvato | G70: Ordinati (RDA) | H70: Residui Accettato | I70: Residui Ordinato | V70: 236 | W70: Frontend | X70: Realizzazione Single Page Application | Y70: 600 | Z70: 980 | AA70: 2880 | AC70: 98 | AD70: 294 | AE70: 490 | AG70: 100416
B71: TOW02.1 | C71: 410 | D71: 3607 | E71: =C71*D71 -> 1478870 | F71: =(SUMIFS(MEV[TOW02.1],MEV[Stato],"approvato",MEV[Tipo Contratto],"BASE"))*D71 -> 172400.17 | G71: =SUMIFS(ORDINI[Valore Posizione],ORDINI[TOW],B71,ORDINI[Listino],"BASE") -> 0 | H71: =E71-F71 -> 1306469.8 | I71: =E71-G71 -> 1478870 | J71: =G71/E71 -> 0 | K71: =E71/$E$77 -> 0.21516943 | V71: 239 | W71: Backend | X71: Servizio/API/Microservizio | Y71: 750 | Z71: 1200 | AA71: 4050 | AC71: 120 | AD71: 360 | AE71: 600 | AG71: 482640
B72: TOW02.2 | C72: 140 | D72: 9018 | E72: =C72*D72 -> 1262520 | F72: =(SUMIFS(MEV[TOW02.2],MEV[Stato],"approvato",MEV[Tipo Contratto],"BASE"))*D72 -> 0 | G72: =SUMIFS(ORDINI[Valore Posizione],ORDINI[TOW],B72,ORDINI[Listino],"BASE") -> 0 | H72: =E72-F72 -> 1262520 | I72: =E72-G72 -> 1262520 | J72: =G72/E72 -> 0 | K72: =E72/$E$77 -> 0.1836914 | V72: 241 | W72: Database | X72: Realizzazione schema (DDL) | Y72: 200 | Z72: 294 | AA72: 1020 | AC72: 29.4 | AD72: 88.2 | AE72: 147 | AG72: 294676.4
B73: TOW02.3 | C73: 410 | D73: 3156 | E73: =C73*D73 -> 1293960 | F73: =(SUMIFS(MEV[TOW02.3],MEV[Stato],"approvato",MEV[Tipo Contratto],"BASE"))*D73 -> 94092.037 | G73: =SUMIFS(ORDINI[Valore Posizione],ORDINI[TOW],B73,ORDINI[Listino],"BASE") -> 0 | H73: =E73-F73 -> 1199868 | I73: =E73-G73 -> 1293960 | J73: =G73/E73 -> 0 | K73: =E73/$E$77 -> 0.18826579 | V73: 242 | W73: Database | X73: Realizzazione stored procedure, script SQL o equivalente | Y73: 120 | Z73: 300 | AA73: 630 | AC73: 30 | AD73: 90 | AE73: 150 | AG73: 136500
B74: TOW02.4 | C74: 410 | D74: 1202 | E74: =C74*D74 -> 492820 | F74: =(SUMIFS(MEV[TOW02.4],MEV[Stato],"approvato",MEV[Tipo Contratto],"BASE"))*D74 -> 42622.92 | G74: =SUMIFS(ORDINI[Valore Posizione],ORDINI[TOW],B74,ORDINI[Listino],"BASE") -> 0 | H74: =E74-F74 -> 450197.08 | I74: =E74-G74 -> 492820 | J74: =G74/E74 -> 0 | K74: =E74/$E$77 -> 0.071703258 | V74: 249 | W74: Data platform | X74: Procedure di caricamento, elaborazione e trasformazione dei dati (ETL) | Y74: 120 | Z74: 300 | AA74: 630 | AC74: 30 | AD74: 90 | AE74: 150 | AG74: 50370
B75: TOW02.5 | E75: 2190247 | F75: =SUMIFS(MEV[TOW02.5],MEV[Stato],"approvato",MEV[Tipo Contratto],"BASE") -> 435700.5 | G75: =SUMIFS(ORDINI[Valore Posizione],ORDINI[TOW],B75,ORDINI[Listino],"BASE") -> 0 | H75: =E75-F75 -> 1754546.5 | I75: =E75-G75 -> 2190247 | J75: =G75/E75 -> 0 | K75: =E75/$E$77 -> 0.31867181 | V75: 406 | W75: Database | X75: Tracciatura - Configurazione (Prodotto, Servizio, altro) | Z75: 1080 | AC75: 108 | AD75: 324 | AE75: 540 | AG75: 113400
B76: TOW02.6 | C76: 24 | D76: 6443 | E76: =C76*D76 -> 154632 | F76: =(SUMIFS(MEV[TOW02.6],MEV[Stato],"approvato",MEV[Tipo Contratto],"BASE"))*D76 -> 38658 | G76: =SUMIFS(ORDINI[Valore Posizione],ORDINI[TOW],B76,ORDINI[Listino],"BASE") -> 38658 | H76: =E76-F76 -> 115974 | I76: =E76-G76 -> 115974 | J76: =G76/E76 -> 0.25 | K76: =E76/$E$77 -> 0.022498312 | V76: 410 | W76: Data platform | X76: Tracciatura - Shell Script File-System HDFS e Gestione Job | Z76: 3750 | AC76: 375 | AD76: 1125 | AE76: 1875 | AG76: 49500
B77: TOTALE | E77: =SUM(E71:E76) -> 6873049 | F77: =SUM(F71:F76) -> 783473.63 | G77: =SUM(G71:G76) -> 38658 | H77: =SUM(H71:H76) -> 6089575.3 | I77: =SUM(I71:I76) -> 6834391 | V77: 412 | W77: Data platform | X77: Tracciatura - Workflow Oozie | Z77: 1200 | AC77: 120 | AD77: 360 | AE77: 600 | AG77: 9720
V78: 413 | W78: Data platform | X78: Tracciatura - Coordinator Oozie | Z78: 600 | AC78: 60 | AD78: 180 | AE78: 300 | AG78: 4320
E79: =E77/2 -> 3436524.5 | V79: 415 | W79: Data platform | X79: Job Spark Streaming e Batch | Y79: 600 | Z79: 2070 | AA79: 5600 | AC79: 207 | AD79: 621 | AE79: 1035 | AG79: 159901
E80: =E79*0.9 -> 3092872 | V80: 416 | W80: Data platform | X80: Tracciatura - Logistica - Job / Template Ni-Fi e Job pubblicazione su SOLr | Z80: 2160 | AC80: 216 | AD80: 648 | AE80: 1080 | AG80: 122040
B81: task | F81: =D76*12 -> 77316 | V81: 418 | W81: Data platform | X81: Tracciatura - Collection / Shard SOLr | Z81: 1680 | AC81: 168 | AD81: 504 | AE81: 840 | AG81: 47880
B82: Canone | F82: =E80-F81 -> 3015556 | V82: 420 | W82: Data platform | X82: Tracciatura - Request Handler SOLr | Y82: 360 | Z82: 840 | AA82: 2100 | AC82: 84 | AD82: 252 | AE82: 420 | AG82: 22272
B83: IET | F83: =E79*0.1 -> 343652.45 | V83: 453 | W83: SAP | X83: SAP Custom using Dialog (module pool) | Z83: 1360 | AC83: 136 | AD83: 408 | AE83: 680 | AG83: 61472
F84: =SUM(F81:F83) -> 3436524.5 | V84: 462 | W84: SAP | X84: SAP STD Enhancement | Z84: 540 | AC84: 54 | AD84: 162 | AE84: 270 | AG84: 6048
F85: =F84*2 -> 6873049 | V85: 481 | W85: Backend | X85: Logistica - Pipeline (Oracle OSB) | Y85: 120 | Z85: 630 | AA85: 1050 | AC85: 63 | AD85: 189 | AE85: 315 | AG85: 37476
V86: 483 | W86: Backend | X86: Logistica - Bridge (JBOSS, WLS) | Y86: € - | Z86: 300 | AA86: € - | AC86: 30 | AD86: 90 | AE86: 150 | AG86: 7830
...

Sheet Catalogo
D1: P. OFFERTO REALIZZAZIONE | G1: PREZZO OFFERTO MODIFICA | J1: TOTALE
A2: ID | B2: Ambito driver | C2: Nome Driver | D2: Semplice | E2: Medio | F2: Complesso | G2: Pz. Semplice | H2: Pz. Medio | I2: Pz. Complesso
A3: 236 | B3: Frontend | C3: Realizzazione Single Page Application | D3: 600 | E3: 980 | F3: 2880 | G3: 98 | H3: 294 | I3: 490 | J3: 100416
A4: 239 | B4: Backend | C4: Servizio/API/Microservizio | D4: 750 | E4: 1200 | F4: 4050 | G4: 120 | H4: 360 | I4: 600 | J4: 482640
A5: 241 | B5: Database | C5: Realizzazione schema (DDL) | D5: 200 | E5: 294 | F5: 1020 | G5: 29.4 | H5: 88.2 | I5: 147 | J5: 294676.4
A6: 242 | B6: Database | C6: Realizzazione stored procedure, script SQL o equivalente | D6: 120 | E6: 300 | F6: 630 | G6: 30 | H6: 90 | I6: 150 | J6: 136500
A7: 249 | B7: Data platform | C7: Procedure di caricamento, elaborazione e trasformazione dei dati (ETL) | D7: 120 | E7: 300 | F7: 630 | G7: 30 | H7: 90 | I7: 150 | J7: 50370
A8: 406 | B8: Database | C8: Tracciatura - Configurazione (Prodotto, Servizio, altro) | E8: 1080 | G8: 108 | H8: 324 | I8: 540 | J8: 113400
A9: 410 | B9: Data platform | C9: Tracciatura - Shell Script File-System HDFS e Gestione Job | E9: 3750 | G9: 375 | H9: 1125 | I9: 1875 | J9: 49500
A10: 412 | B10: Data platform | C10: Tracciatura - Workflow Oozie | E10: 1200 | G10: 120 | H10: 360 | I10: 600 | J10: 9720
A11: 413 | B11: Data platform | C11: Tracciatura - Coordinator Oozie | E11: 600 | G11: 60 | H11: 180 | I11: 300 | J11: 4320
A12: 415 | B12: Data platform | C12: Job Spark Streaming e Batch | D12: 600 | E12: 2070 | F12: 5600 | G12: 207 | H12: 621 | I12: 1035 | J12: 159901
A13: 416 | B13: Data platform | C13: Tracciatura - Logistica - Job / Template Ni-Fi e Job pubblicazione su SOLr | E13: 2160 | G13: 216 | H13: 648 | I13: 1080 | J13: 122040
A14: 418 | B14: Data platform | C14: Tracciatura - Collection / Shard SOLr | E14: 1680 | G14: 168 | H14: 504 | I14: 840 | J14: 47880
A15: 420 | B15: Data platform | C15: Tracciatura - Request Handler SOLr | D15: 360 | E15: 840 | F15: 2100 | G15: 84 | H15: 252 | I15: 420 | J15: 22272
A16: 453 | B16: SAP | C16: SAP Custom using Dialog (module pool) | E16: 1360 | G16: 136 | H16: 408 | I16: 680 | J16: 61472
A17: 462 | B17: SAP | C17: SAP STD Enhancement | E17: 540 | G17: 54 | H17: 162 | I17: 270 | J17: 6048
A18: 481 | B18: Backend | C18: Logistica - Pipeline (Oracle OSB) | D18: 120 | E18: 630 | F18: 1050 | G18: 63 | H18: 189 | I18: 315 | J18: 37476
A19: 483 | B19: Backend | C19: Logistica - Bridge (JBOSS, WLS) | D19: € - | E19: 300 | F19: € - | G19: 30 | H19: 90 | I19: 150 | J19: 7830
A20: 498 | B20: Backend | C20: Logistica - Creazione BPEL | D20: 75 | E20: 225 | F20: 708.3 | G20: 22.5 | H20: 67.5 | I20: 112.5 | J20: 48457.2
A21: 952 | B21: SAP | C21: Bapi | D21: 237.6 | E21: 495 | F21: 1815 | G21: 49.5 | H21: 148.5 | I21: 247.5 | J21: 42028.8
A22: 954 | B22: SAP | C22: Flussi Batch Inbound | D22: 237.6 | E22: 495 | F22: 1650 | G22: 49.5 | H22: 148.5 | I22: 247.5 | J22: 71728.8
A23: 955 | B23: SAP | C23: Flussi Batch Outbound | D23: 173.4 | E23: 420 | F23: 982.8 | G23: 42 | H23: 126 | I23: 210 | J23: 54525
A24: 965 | B24: SAP | C24: Tabella/Strutture | D24: 38.25 | E24: 75 | F24: 270 | G24: 7.5 | H24: 22.5 | I24: 37.5 | J24: 12033
A25: 966 | B25: SAP | C25: Customizing | D25: 38.25 | E25: 150 | F25: 900 | G25: 15 | H25: 45 | I25: 75 | J25: 13852.5
A26: 967 | B26: SAP | C26: Definizione Ruoli/Profili ABAP | D26: 38.25 | E26: 165 | F26: 420 | G26: 16.5 | H26: 49.5 | I26: 82.5 | J26: 31763.25
A27: 992 | B27: Backend | C27: Consumer | D27: 255 | E27: 570 | F27: 1080 | G27: 57 | H27: 171 | I27: 285 | J27: 86685
A28: 993 | B28: Backend | C28: Producer | D28: 255 | E28: 570 | F28: 1080 | G28: 57 | H28: 171 | I28: 285 | J28: 75840
A29: 1025 | B29: SAP | C29: Creazione WS inbound (SOAP o Rest) | D29: 510 | E29: 900 | F29: 2268 | G29: 90 | H29: 270 | I29: 450 | J29: 46872
J30: =SUM(J3:J29) -> 2190247
E33: =3244/E8 -> 3.0037037
G34: =G4*4 -> 480
G35: =G34+H4 -> 840

Sheet MEV
AJ1: SUBCO
A2: ID | B2: GoTo | C2: Applicativo | D2: X ORDINE | E2: Descrizione | F2: PM POSTE | G2: PM CAP | H2: Anno Competenza | I2: Release | J2: Capgemini | K2: IET | L2: Stato | M2: Importo Fornitura | N2: Tipo Contratto | O2: Importo Fornitura scontato | P2: Note | Q2: Data Check Poste | R2: Elapsed da approvazione | S2: Fase Lavorazione | T2: Data rilascio collaudo | U2: BC | V2: Contratto | W2: AT ID | X2: TOW02.1 | Y2: TOW02.2 | Z2: TOW02.3 | AA2: TOW02.4 | AB2: TOW02.5 | AC2: TOW02.6 | AD2: Totale | AE2: Ordinato (BdO) | AF2: Fatturato | AG2: Residuo fatturabile | AH2: Tabella Offerta | AI2: Colonna1 | AJ2: SUBCO | AK2: Nome | AL2: Offerta (€) | AM2: Documento Offerta | AN2: Accantonato | AO2: NEL | AP2: In Vita
A3: 1 | B3: 137341 | C3: WIPI | D3: =CONCATENATE(MEV[[#This Row],[GoTo]],"_",MEV[[#This Row],[Applicativo]]) -> 137341_WIPI | E3: Elaborazione REVERSE ITZ PLUS_rev | F3: Sugamiele | G3: Fabbri | H3: 2026 | I3: R.26.03_EXTRA | J3: x | L3: Approvato | M3: 9951.89 | N3: BASE | O3: =IF(MEV[[#This Row],[Importo Fornitura]]>0,MEV[[#This Row],[Importo Fornitura]]-(MEV[[#This Row],[Importo Fornitura]]*VLOOKUP(MEV[[#This Row],[Tipo Contratto]],CONTRATTO!$B$4:$F$15,5,FALSE)),"") -> 9951.89 | P3: 30/03 - depositata stima applicando modalità di stima chiesta da Poste 16/02 - stima inviata a Poste | U3: =VLOOKUP(MEV[[#This Row],[X ORDINE]],ORDINI!$A$2:$I$26,2,FALSE) -> #N/A | V3: =VLOOKUP(MEV[[#This Row],[BC]],CONTRATTO!$B$20:$C$60,2,FALSE) -> #N/A | W3: =VLOOKUP(MEV[[#This Row],[BC]],CONTRATTO!$B$20:$E$60,4,FALSE) -> #N/A | X3: 1.211 | Y3: 0 | Z3: 0.274 | AA3: 0.332 | AB3: 4320 | AD3: =MEV[[#This Row],[TOW02.1]]*CONTRATTO!$D$71+MEV[[#This Row],[TOW02.2]]*CONTRATTO!$D$72+MEV[[#This Row],[TOW02.3]]*CONTRATTO!$D$73+MEV[[#This Row],[TOW02.4]]*CONTRATTO!$D$74+MEV[[#This Row],[TOW02.5]]+MEV[[#This Row],[TOW02.6]]*CONTRATTO!$D$76 -> 9951.885 | AE3: =SUMIF(ORDINI[MEV],MEV[[#This Row],[X ORDINE]],ORDINI[Valore Posizione]) -> 0 | AF3: =SUMIF(ORDINI[MEV],MEV[[#This Row],[X ORDINE]],ORDINI[Totale Fatturato]) -> 0 | AG3: =MEV[[#This Row],[Ordinato (BdO)]]-MEV[[#This Row],[Fatturato]] -> 0 | AH3: =IF(MEV[[#This Row],[Stato]]="Approvato","https://capgemini.sharepoint.com/:f:/r/sites/LOGISTICA-GOVERNANCE2/Shared%20Documents/General/GARA%202025/ECONOMICS/TabelleOfferte/"&MEV[[#This Row],[Release]]&"/Tabella Offerta - "&MEV[[#This Row],[GoTo]]&"_"&MEV[[#This Row],[Applicativo]]&" - "&E3&".xlsx","") -> https://capgemini.sharepoint.com/:f:/r/sites/LOGISTICA-GOVERNANCE2/Shared%20Documents/General/GARA%202025/ECONOMICS/TabelleOfferte/R.26.03_EXTRA/Tabella Offerta - 137341_WIPI - Elaborazione REVERSE ITZ PLUS_rev.xlsx
A4: =A3+1 -> 2 | B4: 137341 | C4: WIPI | D4: =CONCATENATE(MEV[[#This Row],[GoTo]],"_",MEV[[#This Row],[Applicativo]]) -> 137341_WIPI | E4: Elaborazione REVERSE ITZ PLUS - file del 06.03_v1 | F4: Sugamiele | G4: Fabbri | H4: 2026 | I4: R.26.03_EXTRA | J4: x | L4: Approvato | M4: 3322.13 | N4: BASE | O4: =IF(MEV[[#This Row],[Importo Fornitura]]>0,MEV[[#This Row],[Importo Fornitura]]-(MEV[[#This Row],[Importo Fornitura]]*VLOOKUP(MEV[[#This Row],[Tipo Contratto]],CONTRATTO!$B$4:$F$15,5,FALSE)),"") -> 3322.13 | P4: 30/03 - depositata stima applicando modalità di stima chiesta da Poste 11/03 - rilasciata elaborazione a Poste 09/03 - stima inviata con voce catalogo chiesta da Poste 06/03 - stima inviata a Poste | U4: =VLOOKUP(MEV[[#This Row],[X ORDINE]],ORDINI!$A$2:$I$26,2,FALSE) -> #N/A | V4: =VLOOKUP(MEV[[#This Row],[BC]],CONTRATTO!$B$20:$C$60,2,FALSE) -> #N/A | W4: =VLOOKUP(MEV[[#This Row],[BC]],CONTRATTO!$B$20:$E$60,4,FALSE) -> #N/A | X4: 0.147 | Y4: 0 | Z4: 0.137 | AA4: 0.166 | AB4: 2160 | AD4: =MEV[[#This Row],[TOW02.1]]*CONTRATTO!$D$71+MEV[[#This Row],[TOW02.2]]*CONTRATTO!$D$72+MEV[[#This Row],[TOW02.3]]*CONTRATTO!$D$73+MEV[[#This Row],[TOW02.4]]*CONTRATTO!$D$74+MEV[[#This Row],[TOW02.5]]+MEV[[#This Row],[TOW02.6]]*CONTRATTO!$D$76 -> 3322.133 | AE4: =SUMIF(ORDINI[MEV],MEV[[#This Row],[X ORDINE]],ORDINI[Valore Posizione]) -> 0 | AF4: =SUMIF(ORDINI[MEV],MEV[[#This Row],[X ORDINE]],ORDINI[Totale Fatturato]) -> 0 | AG4: =MEV[[#This Row],[Ordinato (BdO)]]-MEV[[#This Row],[Fatturato]] -> 0 | AH4: =IF(MEV[[#This Row],[Stato]]="Approvato","https://capgemini.sharepoint.com/:f:/r/sites/LOGISTICA-GOVERNANCE2/Shared%20Documents/General/GARA%202025/ECONOMICS/TabelleOfferte/"&MEV[[#This Row],[Release]]&"/Tabella Offerta - "&MEV[[#This Row],[GoTo]]&"_"&MEV[[#This Row],[Applicativo]]&" - "&E4&".xlsx","") -> https://capgemini.sharepoint.com/:f:/r/sites/LOGISTICA-GOVERNANCE2/Shared%20Documents/General/GARA%202025/ECONOMICS/TabelleOfferte/R.26.03_EXTRA/Tabella Offerta - 137341_WIPI - Elaborazione REVERSE ITZ PLUS - file del 06.03_v1.xlsx | AR4: https://capgemini.sharepoint.com/:f:/r/sites/LOGISTICA-GOVERNANCE2/Shared%20Documents/General/GARA%202025/ECONOMICS/TabelleOfferte/R.26.03_EXTRA/Tabella Offerta - 137341_WIPI - Elaborazione REVERSE ITZ PLUS - file del 06.03_v1.xlsx
A5: =A4+1 -> 3 | B5: TBD_SW | C5: RECUPERO | D5: =CONCATENATE(MEV[[#This Row],[GoTo]],"_",MEV[[#This Row],[Applicativo]]) -> TBD_SW_RECUPERO | E5: SW | F5: Riggio | H5: 2026 | I5: R.26.05 | J5: x | L5: Approvato | M5: 551000 | N5: BASE | O5: =IF(MEV[[#This Row],[Importo Fornitura]]>0,MEV[[#This Row],[Importo Fornitura]]-(MEV[[#This Row],[Importo Fornitura]]*VLOOKUP(MEV[[#This Row],[Tipo Contratto]],CONTRATTO!$B$4:$F$15,5,FALSE)),"") -> 551000 | U5: =VLOOKUP(MEV[[#This Row],[X ORDINE]],ORDINI!$A$2:$I$26,2,FALSE) -> #N/A | V5: =VLOOKUP(MEV[[#This Row],[BC]],CONTRATTO!$B$20:$C$60,2,FALSE) -> #N/A | W5: =VLOOKUP(MEV[[#This Row],[BC]],CONTRATTO!$B$20:$E$60,4,FALSE) -> #N/A | AD5: =MEV[[#This Row],[TOW02.1]]*CONTRATTO!$D$71+MEV[[#This Row],[TOW02.2]]*CONTRATTO!$D$72+MEV[[#This Row],[TOW02.3]]*CONTRATTO!$D$73+MEV[[#This Row],[TOW02.4]]*CONTRATTO!$D$74+MEV[[#This Row],[TOW02.5]]+MEV[[#This Row],[TOW02.6]]*CONTRATTO!$D$76 -> 0 | AE5: =SUMIF(ORDINI[MEV],MEV[[#This Row],[X ORDINE]],ORDINI[Valore Posizione]) -> 0 | AF5: =SUMIF(ORDINI[MEV],MEV[[#This Row],[X ORDINE]],ORDINI[Totale Fatturato]) -> 0 | AG5: =MEV[[#This Row],[Ordinato (BdO)]]-MEV[[#This Row],[Fatturato]] -> 0 | AH5: =IF(MEV[[#This Row],[Stato]]="Approvato","https://capgemini.sharepoint.com/:f:/r/sites/LOGISTICA-GOVERNANCE2/Shared%20Documents/General/GARA%202025/ECONOMICS/TabelleOfferte/"&MEV[[#This Row],[Release]]&"/Tabella Offerta - "&MEV[[#This Row],[GoTo]]&"_"&MEV[[#This Row],[Applicativo]]&" - "&E5&".xlsx","") -> https://capgemini.sharepoint.com/:f:/r/sites/LOGISTICA-GOVERNANCE2/Shared%20Documents/General/GARA%202025/ECONOMICS/TabelleOfferte/R.26.05/Tabella Offerta - TBD_SW_RECUPERO - SW.xlsx
